[2025-02-11T05:12:40.293+0000] {taskinstance.py:1157} INFO - Dependencies all met for dep_context=non-requeueable deps ti=<TaskInstance: loan_etl.dwh_to_feature_store manual__2025-02-11T05:12:37.601408+00:00 [queued]>
[2025-02-11T05:12:40.303+0000] {taskinstance.py:1157} INFO - Dependencies all met for dep_context=requeueable deps ti=<TaskInstance: loan_etl.dwh_to_feature_store manual__2025-02-11T05:12:37.601408+00:00 [queued]>
[2025-02-11T05:12:40.304+0000] {taskinstance.py:1359} INFO - Starting attempt 1 of 1
[2025-02-11T05:12:40.323+0000] {taskinstance.py:1380} INFO - Executing <Task(PythonOperator): dwh_to_feature_store> on 2025-02-11 05:12:37.601408+00:00
[2025-02-11T05:12:40.330+0000] {standard_task_runner.py:57} INFO - Started process 874 to run task
[2025-02-11T05:12:40.336+0000] {standard_task_runner.py:84} INFO - Running: ['***', 'tasks', 'run', 'loan_etl', 'dwh_to_feature_store', 'manual__2025-02-11T05:12:37.601408+00:00', '--job-id', '70', '--raw', '--subdir', 'DAGS_FOLDER/batch_processing.py', '--cfg-path', '/tmp/tmpwjxxjjks']
[2025-02-11T05:12:40.340+0000] {standard_task_runner.py:85} INFO - Job 70: Subtask dwh_to_feature_store
[2025-02-11T05:12:40.398+0000] {task_command.py:415} INFO - Running <TaskInstance: loan_etl.dwh_to_feature_store manual__2025-02-11T05:12:37.601408+00:00 [running]> on host 94963e7d153a
[2025-02-11T05:12:40.485+0000] {taskinstance.py:1660} INFO - Exporting env vars: AIRFLOW_CTX_DAG_OWNER='***' AIRFLOW_CTX_DAG_ID='loan_etl' AIRFLOW_CTX_TASK_ID='dwh_to_feature_store' AIRFLOW_CTX_EXECUTION_DATE='2025-02-11T05:12:37.601408+00:00' AIRFLOW_CTX_TRY_NUMBER='1' AIRFLOW_CTX_DAG_RUN_ID='manual__2025-02-11T05:12:37.601408+00:00'
[2025-02-11T05:13:04.291+0000] {taskinstance.py:1935} ERROR - Task failed with exception
Traceback (most recent call last):
  File "/home/airflow/.local/lib/python3.11/site-packages/airflow/operators/python.py", line 192, in execute
    return_value = self.execute_callable()
                   ^^^^^^^^^^^^^^^^^^^^^^^
  File "/home/airflow/.local/lib/python3.11/site-packages/airflow/operators/python.py", line 209, in execute_callable
    return self.python_callable(*self.op_args, **self.op_kwargs)
           ^^^^^^^^^^^^^^^^^^^^^^^^^^^^^^^^^^^^^^^^^^^^^^^^^^^^^
  File "/opt/airflow/dags/batch_processing.py", line 17, in etl_dwh_to_feature_store
    etl.execute(app_name="ETL from data warehouse to feature store", table_name="loan")
  File "/opt/airflow/dags/processing/batch/loan_approval_classification/loan_etl.py", line 69, in execute
    df = self.extract(spark, table_name)
         ^^^^^^^^^^^^^^^^^^^^^^^^^^^^^^^
  File "/opt/airflow/dags/processing/batch/loan_approval_classification/loan_etl.py", line 45, in extract
    .load()
     ^^^^^^
  File "/home/airflow/.local/lib/python3.11/site-packages/pyspark/sql/readwriter.py", line 314, in load
    return self._df(self._jreader.load())
                    ^^^^^^^^^^^^^^^^^^^^
  File "/home/airflow/.local/lib/python3.11/site-packages/py4j/java_gateway.py", line 1322, in __call__
    return_value = get_return_value(
                   ^^^^^^^^^^^^^^^^^
  File "/home/airflow/.local/lib/python3.11/site-packages/pyspark/errors/exceptions/captured.py", line 179, in deco
    return f(*a, **kw)
           ^^^^^^^^^^^
  File "/home/airflow/.local/lib/python3.11/site-packages/py4j/protocol.py", line 326, in get_return_value
    raise Py4JJavaError(
py4j.protocol.Py4JJavaError: An error occurred while calling o37.load.
: org.postgresql.util.PSQLException: ERROR: relation "loan" does not exist
  Position: 15
	at org.postgresql.core.v3.QueryExecutorImpl.receiveErrorResponse(QueryExecutorImpl.java:2713)
	at org.postgresql.core.v3.QueryExecutorImpl.processResults(QueryExecutorImpl.java:2401)
	at org.postgresql.core.v3.QueryExecutorImpl.execute(QueryExecutorImpl.java:368)
	at org.postgresql.jdbc.PgStatement.executeInternal(PgStatement.java:498)
	at org.postgresql.jdbc.PgStatement.execute(PgStatement.java:415)
	at org.postgresql.jdbc.PgPreparedStatement.executeWithFlags(PgPreparedStatement.java:190)
	at org.postgresql.jdbc.PgPreparedStatement.executeQuery(PgPreparedStatement.java:134)
	at org.apache.spark.sql.execution.datasources.jdbc.JDBCRDD$.getQueryOutputSchema(JDBCRDD.scala:68)
	at org.apache.spark.sql.execution.datasources.jdbc.JDBCRDD$.resolveTable(JDBCRDD.scala:58)
	at org.apache.spark.sql.execution.datasources.jdbc.JDBCRelation$.getSchema(JDBCRelation.scala:241)
	at org.apache.spark.sql.execution.datasources.jdbc.JdbcRelationProvider.createRelation(JdbcRelationProvider.scala:37)
	at org.apache.spark.sql.execution.datasources.DataSource.resolveRelation(DataSource.scala:346)
	at org.apache.spark.sql.DataFrameReader.loadV1Source(DataFrameReader.scala:229)
	at org.apache.spark.sql.DataFrameReader.$anonfun$load$2(DataFrameReader.scala:211)
	at scala.Option.getOrElse(Option.scala:189)
	at org.apache.spark.sql.DataFrameReader.load(DataFrameReader.scala:211)
	at org.apache.spark.sql.DataFrameReader.load(DataFrameReader.scala:172)
	at java.base/jdk.internal.reflect.NativeMethodAccessorImpl.invoke0(Native Method)
	at java.base/jdk.internal.reflect.NativeMethodAccessorImpl.invoke(NativeMethodAccessorImpl.java:62)
	at java.base/jdk.internal.reflect.DelegatingMethodAccessorImpl.invoke(DelegatingMethodAccessorImpl.java:43)
	at java.base/java.lang.reflect.Method.invoke(Method.java:566)
	at py4j.reflection.MethodInvoker.invoke(MethodInvoker.java:244)
	at py4j.reflection.ReflectionEngine.invoke(ReflectionEngine.java:374)
	at py4j.Gateway.invoke(Gateway.java:282)
	at py4j.commands.AbstractCommand.invokeMethod(AbstractCommand.java:132)
	at py4j.commands.CallCommand.execute(CallCommand.java:79)
	at py4j.ClientServerConnection.waitForCommands(ClientServerConnection.java:182)
	at py4j.ClientServerConnection.run(ClientServerConnection.java:106)
	at java.base/java.lang.Thread.run(Thread.java:829)

[2025-02-11T05:13:04.364+0000] {taskinstance.py:1398} INFO - Marking task as FAILED. dag_id=loan_etl, task_id=dwh_to_feature_store, execution_date=20250211T051237, start_date=20250211T051240, end_date=20250211T051304
[2025-02-11T05:13:04.398+0000] {standard_task_runner.py:104} ERROR - Failed to execute job 70 for task dwh_to_feature_store (An error occurred while calling o37.load.
: org.postgresql.util.PSQLException: ERROR: relation "loan" does not exist
  Position: 15
	at org.postgresql.core.v3.QueryExecutorImpl.receiveErrorResponse(QueryExecutorImpl.java:2713)
	at org.postgresql.core.v3.QueryExecutorImpl.processResults(QueryExecutorImpl.java:2401)
	at org.postgresql.core.v3.QueryExecutorImpl.execute(QueryExecutorImpl.java:368)
	at org.postgresql.jdbc.PgStatement.executeInternal(PgStatement.java:498)
	at org.postgresql.jdbc.PgStatement.execute(PgStatement.java:415)
	at org.postgresql.jdbc.PgPreparedStatement.executeWithFlags(PgPreparedStatement.java:190)
	at org.postgresql.jdbc.PgPreparedStatement.executeQuery(PgPreparedStatement.java:134)
	at org.apache.spark.sql.execution.datasources.jdbc.JDBCRDD$.getQueryOutputSchema(JDBCRDD.scala:68)
	at org.apache.spark.sql.execution.datasources.jdbc.JDBCRDD$.resolveTable(JDBCRDD.scala:58)
	at org.apache.spark.sql.execution.datasources.jdbc.JDBCRelation$.getSchema(JDBCRelation.scala:241)
	at org.apache.spark.sql.execution.datasources.jdbc.JdbcRelationProvider.createRelation(JdbcRelationProvider.scala:37)
	at org.apache.spark.sql.execution.datasources.DataSource.resolveRelation(DataSource.scala:346)
	at org.apache.spark.sql.DataFrameReader.loadV1Source(DataFrameReader.scala:229)
	at org.apache.spark.sql.DataFrameReader.$anonfun$load$2(DataFrameReader.scala:211)
	at scala.Option.getOrElse(Option.scala:189)
	at org.apache.spark.sql.DataFrameReader.load(DataFrameReader.scala:211)
	at org.apache.spark.sql.DataFrameReader.load(DataFrameReader.scala:172)
	at java.base/jdk.internal.reflect.NativeMethodAccessorImpl.invoke0(Native Method)
	at java.base/jdk.internal.reflect.NativeMethodAccessorImpl.invoke(NativeMethodAccessorImpl.java:62)
	at java.base/jdk.internal.reflect.DelegatingMethodAccessorImpl.invoke(DelegatingMethodAccessorImpl.java:43)
	at java.base/java.lang.reflect.Method.invoke(Method.java:566)
	at py4j.reflection.MethodInvoker.invoke(MethodInvoker.java:244)
	at py4j.reflection.ReflectionEngine.invoke(ReflectionEngine.java:374)
	at py4j.Gateway.invoke(Gateway.java:282)
	at py4j.commands.AbstractCommand.invokeMethod(AbstractCommand.java:132)
	at py4j.commands.CallCommand.execute(CallCommand.java:79)
	at py4j.ClientServerConnection.waitForCommands(ClientServerConnection.java:182)
	at py4j.ClientServerConnection.run(ClientServerConnection.java:106)
	at java.base/java.lang.Thread.run(Thread.java:829)
; 874)
[2025-02-11T05:13:04.435+0000] {local_task_job_runner.py:228} INFO - Task exited with return code 1
[2025-02-11T05:13:04.477+0000] {taskinstance.py:2776} INFO - 0 downstream tasks scheduled from follow-on schedule check
