[2025-02-11T16:11:55.066+0000] {taskinstance.py:1157} INFO - Dependencies all met for dep_context=non-requeueable deps ti=<TaskInstance: loan_etl.dwh_to_feature_store manual__2025-02-11T16:11:53.638874+00:00 [queued]>
[2025-02-11T16:11:55.072+0000] {taskinstance.py:1157} INFO - Dependencies all met for dep_context=requeueable deps ti=<TaskInstance: loan_etl.dwh_to_feature_store manual__2025-02-11T16:11:53.638874+00:00 [queued]>
[2025-02-11T16:11:55.073+0000] {taskinstance.py:1359} INFO - Starting attempt 1 of 1
[2025-02-11T16:11:55.079+0000] {taskinstance.py:1380} INFO - Executing <Task(PythonOperator): dwh_to_feature_store> on 2025-02-11 16:11:53.638874+00:00
[2025-02-11T16:11:55.084+0000] {standard_task_runner.py:57} INFO - Started process 116 to run task
[2025-02-11T16:11:55.087+0000] {standard_task_runner.py:84} INFO - Running: ['***', 'tasks', 'run', 'loan_etl', 'dwh_to_feature_store', 'manual__2025-02-11T16:11:53.638874+00:00', '--job-id', '18', '--raw', '--subdir', 'DAGS_FOLDER/batch_processing.py', '--cfg-path', '/tmp/tmp36nr96vx']
[2025-02-11T16:11:55.091+0000] {standard_task_runner.py:85} INFO - Job 18: Subtask dwh_to_feature_store
[2025-02-11T16:11:55.123+0000] {task_command.py:415} INFO - Running <TaskInstance: loan_etl.dwh_to_feature_store manual__2025-02-11T16:11:53.638874+00:00 [running]> on host 3141457a26c3
[2025-02-11T16:11:55.166+0000] {taskinstance.py:1660} INFO - Exporting env vars: AIRFLOW_CTX_DAG_OWNER='***' AIRFLOW_CTX_DAG_ID='loan_etl' AIRFLOW_CTX_TASK_ID='dwh_to_feature_store' AIRFLOW_CTX_EXECUTION_DATE='2025-02-11T16:11:53.638874+00:00' AIRFLOW_CTX_TRY_NUMBER='1' AIRFLOW_CTX_DAG_RUN_ID='manual__2025-02-11T16:11:53.638874+00:00'
[2025-02-11T16:11:55.168+0000] {taskinstance.py:1935} ERROR - Task failed with exception
Traceback (most recent call last):
  File "/home/airflow/.local/lib/python3.11/site-packages/airflow/operators/python.py", line 192, in execute
    return_value = self.execute_callable()
                   ^^^^^^^^^^^^^^^^^^^^^^^
  File "/home/airflow/.local/lib/python3.11/site-packages/airflow/operators/python.py", line 209, in execute_callable
    return self.python_callable(*self.op_args, **self.op_kwargs)
           ^^^^^^^^^^^^^^^^^^^^^^^^^^^^^^^^^^^^^^^^^^^^^^^^^^^^^
  File "/opt/airflow/dags/batch_processing.py", line 17, in etl_dwh_to_feature_store
    etl.execute(app_name="ETL from data warehouse to feature store", table_name="loan")
  File "/opt/airflow/dags/processing/batch/loan_approval_classification/loan_etl.py", line 70, in execute
    df = self.extract(spark, table_name)
         ^^^^^^^^^^^^^^^^^^^^^^^^^^^^^^^
  File "/opt/airflow/dags/processing/batch/loan_approval_classification/loan_etl.py", line 40, in extract
    cur = conn.cursor()
          ^^^^^^^^^^^
AttributeError: 'NoneType' object has no attribute 'cursor'
[2025-02-11T16:11:55.183+0000] {taskinstance.py:1398} INFO - Marking task as FAILED. dag_id=loan_etl, task_id=dwh_to_feature_store, execution_date=20250211T161153, start_date=20250211T161155, end_date=20250211T161155
[2025-02-11T16:11:55.197+0000] {standard_task_runner.py:104} ERROR - Failed to execute job 18 for task dwh_to_feature_store ('NoneType' object has no attribute 'cursor'; 116)
[2025-02-11T16:11:55.225+0000] {local_task_job_runner.py:228} INFO - Task exited with return code 1
[2025-02-11T16:11:55.237+0000] {taskinstance.py:2776} INFO - 0 downstream tasks scheduled from follow-on schedule check
