[2025-02-11T02:45:48.644+0000] {taskinstance.py:1157} INFO - Dependencies all met for dep_context=non-requeueable deps ti=<TaskInstance: loan_etl.dwh_to_feature_store manual__2025-02-11T02:45:47.332264+00:00 [queued]>
[2025-02-11T02:45:48.648+0000] {taskinstance.py:1157} INFO - Dependencies all met for dep_context=requeueable deps ti=<TaskInstance: loan_etl.dwh_to_feature_store manual__2025-02-11T02:45:47.332264+00:00 [queued]>
[2025-02-11T02:45:48.648+0000] {taskinstance.py:1359} INFO - Starting attempt 1 of 1
[2025-02-11T02:45:48.653+0000] {taskinstance.py:1380} INFO - Executing <Task(PythonOperator): dwh_to_feature_store> on 2025-02-11 02:45:47.332264+00:00
[2025-02-11T02:45:48.657+0000] {standard_task_runner.py:57} INFO - Started process 263 to run task
[2025-02-11T02:45:48.659+0000] {standard_task_runner.py:84} INFO - Running: ['***', 'tasks', 'run', 'loan_etl', 'dwh_to_feature_store', 'manual__2025-02-11T02:45:47.332264+00:00', '--job-id', '68', '--raw', '--subdir', 'DAGS_FOLDER/batch_processing.py', '--cfg-path', '/tmp/tmp2auzo1mk']
[2025-02-11T02:45:48.661+0000] {standard_task_runner.py:85} INFO - Job 68: Subtask dwh_to_feature_store
[2025-02-11T02:45:48.711+0000] {task_command.py:415} INFO - Running <TaskInstance: loan_etl.dwh_to_feature_store manual__2025-02-11T02:45:47.332264+00:00 [running]> on host 94963e7d153a
[2025-02-11T02:45:48.764+0000] {taskinstance.py:1660} INFO - Exporting env vars: AIRFLOW_CTX_DAG_OWNER='***' AIRFLOW_CTX_DAG_ID='loan_etl' AIRFLOW_CTX_TASK_ID='dwh_to_feature_store' AIRFLOW_CTX_EXECUTION_DATE='2025-02-11T02:45:47.332264+00:00' AIRFLOW_CTX_TRY_NUMBER='1' AIRFLOW_CTX_DAG_RUN_ID='manual__2025-02-11T02:45:47.332264+00:00'
[2025-02-11T02:45:48.767+0000] {taskinstance.py:1935} ERROR - Task failed with exception
Traceback (most recent call last):
  File "/home/airflow/.local/lib/python3.11/site-packages/airflow/operators/python.py", line 192, in execute
    return_value = self.execute_callable()
                   ^^^^^^^^^^^^^^^^^^^^^^^
  File "/home/airflow/.local/lib/python3.11/site-packages/airflow/operators/python.py", line 209, in execute_callable
    return self.python_callable(*self.op_args, **self.op_kwargs)
           ^^^^^^^^^^^^^^^^^^^^^^^^^^^^^^^^^^^^^^^^^^^^^^^^^^^^^
  File "/opt/airflow/dags/batch_processing.py", line 16, in etl_dwh_to_feature_store
    etl = LoanApprovalETL()
          ^^^^^^^^^^^^^^^^^
  File "/opt/airflow/dags/processing/batch/loan_approval_classification/loan_etl.py", line 17, in __init__
    self.__username = get_env_variable("SILVER_USERNAME")
                      ^^^^^^^^^^^^^^^^^^^^^^^^^^^^^^^^^^^
  File "/opt/airflow/dags/processing/utils.py", line 7, in get_env_variable
    raise ValueError(f"Variable '{variable_name}' not found in environment.")
ValueError: Variable 'SILVER_USERNAME' not found in environment.
[2025-02-11T02:45:48.774+0000] {taskinstance.py:1398} INFO - Marking task as FAILED. dag_id=loan_etl, task_id=dwh_to_feature_store, execution_date=20250211T024547, start_date=20250211T024548, end_date=20250211T024548
[2025-02-11T02:45:48.779+0000] {standard_task_runner.py:104} ERROR - Failed to execute job 68 for task dwh_to_feature_store (Variable 'SILVER_USERNAME' not found in environment.; 263)
[2025-02-11T02:45:48.800+0000] {local_task_job_runner.py:228} INFO - Task exited with return code 1
[2025-02-11T02:45:48.808+0000] {taskinstance.py:2776} INFO - 0 downstream tasks scheduled from follow-on schedule check
