[2025-02-08T10:51:41.784+0000] {taskinstance.py:1157} INFO - Dependencies all met for dep_context=non-requeueable deps ti=<TaskInstance: batch_ingestion.ingest_postgres_to_minio manual__2025-02-08T10:51:41.116043+00:00 [queued]>
[2025-02-08T10:51:41.790+0000] {taskinstance.py:1157} INFO - Dependencies all met for dep_context=requeueable deps ti=<TaskInstance: batch_ingestion.ingest_postgres_to_minio manual__2025-02-08T10:51:41.116043+00:00 [queued]>
[2025-02-08T10:51:41.791+0000] {taskinstance.py:1359} INFO - Starting attempt 1 of 1
[2025-02-08T10:51:41.797+0000] {taskinstance.py:1380} INFO - Executing <Task(PythonOperator): ingest_postgres_to_minio> on 2025-02-08 10:51:41.116043+00:00
[2025-02-08T10:51:41.801+0000] {standard_task_runner.py:57} INFO - Started process 305 to run task
[2025-02-08T10:51:41.804+0000] {standard_task_runner.py:84} INFO - Running: ['***', 'tasks', 'run', 'batch_ingestion', 'ingest_postgres_to_minio', 'manual__2025-02-08T10:51:41.116043+00:00', '--job-id', '8', '--raw', '--subdir', 'DAGS_FOLDER/batch_ingestion.py', '--cfg-path', '/tmp/tmpz7kk4zym']
[2025-02-08T10:51:41.805+0000] {standard_task_runner.py:85} INFO - Job 8: Subtask ingest_postgres_to_minio
[2025-02-08T10:51:41.835+0000] {task_command.py:415} INFO - Running <TaskInstance: batch_ingestion.ingest_postgres_to_minio manual__2025-02-08T10:51:41.116043+00:00 [running]> on host 08b2804f1694
[2025-02-08T10:51:41.884+0000] {taskinstance.py:1660} INFO - Exporting env vars: AIRFLOW_CTX_DAG_OWNER='***' AIRFLOW_CTX_DAG_ID='batch_ingestion' AIRFLOW_CTX_TASK_ID='ingest_postgres_to_minio' AIRFLOW_CTX_EXECUTION_DATE='2025-02-08T10:51:41.116043+00:00' AIRFLOW_CTX_TRY_NUMBER='1' AIRFLOW_CTX_DAG_RUN_ID='manual__2025-02-08T10:51:41.116043+00:00'
[2025-02-08T10:51:42.003+0000] {taskinstance.py:1935} ERROR - Task failed with exception
Traceback (most recent call last):
  File "/home/airflow/.local/lib/python3.8/site-packages/airflow/operators/python.py", line 192, in execute
    return_value = self.execute_callable()
  File "/home/airflow/.local/lib/python3.8/site-packages/airflow/operators/python.py", line 209, in execute_callable
    return self.python_callable(*self.op_args, **self.op_kwargs)
  File "/opt/airflow/dags/batch_ingestion.py", line 16, in ingest_postgres_to_minio
    ptm.read(table_name="loan", app_name="Batch ingestion from PostgreSQL to Minio")
  File "/opt/airflow/dags/ingestion/batch/postgres_to_minio/postgres_to_minio.py", line 48, in read
    spark = self.create_spark_session(app_name)
  File "/opt/airflow/dags/ingestion/batch/postgres_to_minio/postgres_to_minio.py", line 30, in create_spark_session
    spark = SparkSession.builder \
  File "/home/airflow/.local/lib/python3.8/site-packages/pyspark/sql/session.py", line 497, in getOrCreate
    sc = SparkContext.getOrCreate(sparkConf)
  File "/home/airflow/.local/lib/python3.8/site-packages/pyspark/context.py", line 515, in getOrCreate
    SparkContext(conf=conf or SparkConf())
  File "/home/airflow/.local/lib/python3.8/site-packages/pyspark/context.py", line 201, in __init__
    SparkContext._ensure_initialized(self, gateway=gateway, conf=conf)
  File "/home/airflow/.local/lib/python3.8/site-packages/pyspark/context.py", line 436, in _ensure_initialized
    SparkContext._gateway = gateway or launch_gateway(conf)
  File "/home/airflow/.local/lib/python3.8/site-packages/pyspark/java_gateway.py", line 107, in launch_gateway
    raise PySparkRuntimeError(
pyspark.errors.exceptions.base.PySparkRuntimeError: [JAVA_GATEWAY_EXITED] Java gateway process exited before sending its port number.
[2025-02-08T10:51:42.015+0000] {taskinstance.py:1398} INFO - Marking task as FAILED. dag_id=batch_ingestion, task_id=ingest_postgres_to_minio, execution_date=20250208T105141, start_date=20250208T105141, end_date=20250208T105142
[2025-02-08T10:51:42.041+0000] {standard_task_runner.py:104} ERROR - Failed to execute job 8 for task ingest_postgres_to_minio ([JAVA_GATEWAY_EXITED] Java gateway process exited before sending its port number.; 305)
[2025-02-08T10:51:42.071+0000] {local_task_job_runner.py:228} INFO - Task exited with return code 1
[2025-02-08T10:51:42.081+0000] {taskinstance.py:2776} INFO - 0 downstream tasks scheduled from follow-on schedule check
